<?xml version="1.0"?>
<robot xmlns:xacro="http://www.ros.org/wiki/xacro">

    <xacro:property name="package_name" value="diff_robot" />
    <xacro:property name="robot_name" value="andino" />

    <xacro:include filename="$(find ${package_name})/description/common_macros.urdf.xacro" />
    <xacro:include filename="$(find ${package_name})/description/common_sensors.urdf.xacro" />
    <xacro:include filename="$(find ${package_name})/description/andino_caster_macro.urdf.xacro" />
    <xacro:include filename="inertial_macros.xacro" />

    <xacro:arg name="yaml_config_dir" default="$(find ${package_name})/config/${robot_name}" />

    <xacro:property name="caster_wheel_yaml" value="$(arg yaml_config_dir)/caster_wheel.yaml" />
    <xacro:property name="caster_wheel_props" value="${xacro.load_yaml(caster_wheel_yaml)}" />

    <xacro:arg name="use_fixed_caster" default="True" />
    <xacro:arg name="use_real_ros_control" default="True" />

    <xacro:property name="base_yaml" value="$(arg yaml_config_dir)/base.yaml" />
    <xacro:property name="base_props" value="${xacro.load_yaml(base_yaml)}"/>
    <xacro:property name="wheel_yaml" value="$(arg yaml_config_dir)/wheel.yaml" />
    <xacro:property name="wheel_props" value="${xacro.load_yaml(wheel_yaml)}" />
    <xacro:property name="sensor_yaml" value="$(arg yaml_config_dir)/sensors.yaml" />
    <xacro:property name="sensor_prop" value="${xacro.load_yaml(sensor_yaml)}" />


    <!-- Footprint -->
    <xacro:footprint wheel_props="${wheel_props}" />

    <!-- Base link -->

    <link name="base_link">

    </link>
    <!-- Chassis link -->
    <joint name="chassis" type="fixed">
        <parent link="base_link" />
        <child link="chassis" />
        <origin xyz="-0.1 0.0 0.0" />
    </joint>

    <link name="chassis">
        <visual>
            <origin xyz="0.05 0.0 0.075" />
            <geometry>
                <box size="0.23 0.15 0.075" />
            </geometry>
            <material name="white" />
        </visual>
        <collision>
            <origin xyz="0.05 0.0 0.075" />
            <geometry>
                <box size="0.23 0.15 0.075" />
            </geometry>
            <material name="white" />
        </collision>
        <xacro:inertial_box mass="0.5" x="0.3" y="0.3" z="0.15">
            <origin xyz="0.05 0 0.075" rpy="0 0 0" />
        </xacro:inertial_box>
    </link>

    <gazebo reference="chassis">
        <material>Gazebo/White</material>
    </gazebo>

    <!-- Wheels -->
    <!-- <xacro:wheel prefix="right" reflect="-1"
        wheel_props="${wheel_props}"
        base_props="${base_props}">
    </xacro:wheel>

    <xacro:wheel prefix="left" reflect="1"
        wheel_props="${wheel_props}"
        base_props="${base_props}">
    </xacro:wheel> -->

    <!-- left wheel link -->
    <joint name="left_wheel_joint" type="continuous">
        <parent link="base_link" />
        <child link="left_wheel" />
        <origin xyz="0 0.1 0.0" rpy="${pi/2} 0 0" />
        <axis xyz="0 0 -1" />
    </joint>

    <link name="left_wheel">
        <visual>
            <geometry>
                <!-- <cylinder radius="0.031" length="0.025" /> -->
                <mesh
                filename="file://$(find diff_robot)/meshes//components/wheel.stl" />
            </geometry>
            <material name="blue" />
        </visual>
        <collision>
            <geometry>
                <sphere radius="0.031" />
            </geometry>
        </collision>
        <xacro:inertial_cylinder mass="0.1" length="0.025" radius="0.031">
            <origin xyz="0 0 0" rpy="0 0 0" />
        </xacro:inertial_cylinder>
    </link>
    <gazebo reference="left_wheel">
        <material>Gazebo/Blue</material>
    </gazebo>

    <!-- right wheel link -->
    <joint name="right_wheel_joint" type="continuous">
        <parent link="base_link" />
        <child link="right_wheel" />
        <origin xyz="0 -0.1 0.0" rpy="-${pi/2} 0 0" />
        <axis xyz="0 0 1" />
    </joint>

    <link name="right_wheel">
        <visual>
            <geometry>
                <!-- <cylinder radius="0.031" length="0.025" /> -->
                <mesh
                filename="file://$(find diff_robot)/meshes//components/wheel.stl" />
            </geometry>
            <material name="blue" />
        </visual>
        <collision>
            <geometry>
                <sphere radius="0.031" />
            </geometry>
        </collision>
        <xacro:inertial_cylinder mass="0.1" length="0.025" radius="0.031">
            <origin xyz="0 0 0" rpy="0 0 0" />
        </xacro:inertial_cylinder>
    </link>
    <gazebo reference="right_wheel">
        <material>Gazebo/Blue</material>
    </gazebo>

    <!-- caster wheel link -->

    <joint name="caster_wheel_joint" type="fixed">
        <parent link="chassis" />
        <child link="caster_wheel" />
        <origin xyz="-0.03 0.0 -0.0" />
    </joint>

    <link name="caster_wheel">
        <visual>
            <geometry>
                <sphere radius="0.035" />
            </geometry>
            <material name="black" />
        </visual>
        <collision>
            <geometry>
                <sphere radius="0.025" />
            </geometry>
        </collision>
        <xacro:inertial_sphere mass="0.1" radius="0.025">
            <origin xyz="0 0 0" rpy="0 0 0" />
        </xacro:inertial_sphere>
    </link>
    <gazebo reference="caster_wheel">
        <material>Gazebo/White</material>
        <mu1 value="0.001" />
        <mu2 value="0.001" />
    </gazebo>

    <!-- <xacro:caster_wheel reflect="-1" use_fixed="$(arg use_fixed_caster)"
        wheel_props="${caster_wheel_props}">
    </xacro:caster_wheel> -->

    <xacro:laser prefix="rplidar" parent_link="chassis" sensor_prop="${sensor_prop}">
    </xacro:laser>

</robot>